Workbook

Sheet Executive Summary
A1: UBER TECHNOLOGIES (NYSE: UBER) — INVESTMENT MEMO DASHBOARD
A2: Portfolio case study by Omar Quinn. NOT investment advice. Figures link to the model tabs; every input is sourced on the Sources tab.
A4: RECOMMENDATION | E4: CENTRAL QUESTION
A5: Qualified BUY / Accumulate (Constructive) | E5: Is Uber attractively valued on growth, margin expansion, FCF generation and risk? Base case: yes, with meaningful upside — but the autonomous-vehicle bear case is severe, so position sizing and monitoring are essential.
A8: VALUATION SCORECARD
A9: Current share price | B9: =Assumptions!C8 -> 73
A10: Bear case (downside stress) | B10: ='Scenario Analysis'!C10 -> 33.156087 | E10: KEY FY2025 METRICS (US$mm)
A11: Base case fair value | B11: ='Scenario Analysis'!D10 -> 103.17966 | E11: Gross Bookings | F11: ='Historical Financials'!G5 -> 193454
A12: Bull case fair value | B12: ='Scenario Analysis'!E10 -> 163.61565 | E12: Revenue | F12: ='Historical Financials'!G7 -> 52017
A13: Probability-weighted fair value | B13: ='Scenario Analysis'!C14 -> 100.78277 | E13: Adjusted EBITDA | F13: ='Historical Financials'!G10 -> 8730
A14: Base-case upside / (downside) | B14: =Valuation!C27 -> 0.41342007 | E14: Free cash flow (reported) | F14: ='Historical Financials'!G15 -> 9763
A15: Prob-weighted upside / (downside) | B15: ='Scenario Analysis'!E14 -> 0.38058583 | E15: Net income (attributable) | F15: ='Historical Financials'!G13 -> 10053
A17: INVESTMENT THESIS (5 POINTS) | E17: FY2025 take rate ≈ 26.9%; FCF up sharply YoY; first full GAAP-profitable year aided by a deferred-tax benefit.
A18: 1. Category-leading two-sided marketplace in Mobility + Delivery with deepening network effects and Uber One cross-sell.
A19: 2. Operating leverage: Adj. EBITDA margin on gross bookings is still expanding from a low base as fixed costs scale.
A20: 3. Free-cash-flow inflection — FCF has gone from negative (2021) to multi-billion positive, with high EBITDA-to-FCF conversion.
A21: 4. Asset-light model (low capex) and ~$7.6bn cash give optionality and buyback capacity ($3bn repurchase underway). | E21: KPIs TO MONITOR NEXT QUARTER
A22: 5. Embedded optionality in equity stakes (Aurora/Grab/Didi) and AV partnerships rather than owning the AV stack. | E22: • Gross-bookings growth (cc) vs guidance of ~18–22%.
E23: • Mobility & Delivery segment Adj. EBITDA margin trajectory.
A24: TOP RISKS / BEAR CASE | E24: • FCF conversion and buyback pace.
A25: • Autonomous-vehicle disruption — Waymo/Tesla could disintermediate drivers and compress Mobility economics. | E25: • AV partnership rollout / city launches and any driver-supply impact.
A26: • Regulatory & labor — driver-classification rulings (e.g. NYC) raise cost or reclassify the workforce. | E26: • Regulatory headlines (labor classification, antitrust).
A27: • Competition & margin pressure — incentives war in Delivery / rideshare caps take rate and EBITDA margin.
A28: • Multiple compression — a high terminal-value share of DCF means rich-but-fragile to WACC / growth shifts. | E28: WHAT THE MARKET MAY BE MIS-PRICING
A29: • Macro sensitivity — discretionary mobility & delivery demand soften in a downturn. | E29: Bear view (priced in the ~28% drawdown from the 2025 high): AV competition structurally caps Uber. Bull view: Uber's demand aggregation, data and Uber One make it the default AV demand layer, monetising fleets it doesn't own. The wide bear-to-bull spread is the debate; the probability-weighted value sits modestly above the current price.
A31: DISCLAIMER
A32: Educational portfolio case study only — NOT investment advice and not a recommendation to buy or sell any security. The author is not a licensed financial advisor. All figures are from cited public filings (see Sources tab) or are clearly labelled assumptions. Forward estimates are illustrative and will differ from actual results.

Sheet Sources
A1: UBER TECHNOLOGIES, INC. (NYSE: UBER) — Investment Memo & Downside Valuation Stress Test
A2: Sources & data provenance | Portfolio case study by Omar Quinn | NOT investment advice | Prepared June 2026
A4: All historical financials below are taken directly from Uber's SEC filings and earnings releases. Forward-looking assumptions in this model are the analyst's own estimates (flagged BLUE) and are NOT company guidance except where explicitly labelled. Figures in US$ millions unless stated.
A8: # | B8: Data / item used | C8: Source document | D8: Period / date | E8: Reference URL
A9: 1 | B9: FY2025 & FY2024 full-year revenue, gross bookings, adj. EBITDA, FCF, segment splits, balance sheet, income statement | C9: Form 8-K (Ex-99.1) — Q4 & FY2025 earnings release | D9: Year ended 12/31/2025 (rel. 2/4/2026) | E9: sec.gov/Archives/edgar/data/1543151/000154315126000011/uberq425earningspressrelea.htm
A10: 2 | B10: Q1 2026 revenue, gross bookings, adj. EBITDA, FCF, cash, buyback, Q2 2026 guidance | C10: Form 8-K (Ex-99.1) — Q1 2026 earnings release | D10: Quarter ended 3/31/2026 (rel. 5/6/2026) | E10: sec.gov/Archives/edgar/data/1543151/000154315126000019/uberq126earningspressrelea.htm
A11: 3 | B11: FY2025 Annual Report financial & operational highlights (MAPCs, trips, GB, revenue, EBITDA, FCF) | C11: Form ARS / 10-K — FY2025 | D11: Year ended 12/31/2025 | E11: sec.gov/Archives/edgar/data/1543151/000155278126000148/e26089_uber-ars.pdf
A12: 4 | B12: Form 10-K FY2025 (risk factors, debt schedule, segment detail) | C12: Form 10-K — FY2025 | D12: Filed Feb 2026 | E12: sec.gov/Archives/edgar/data/1543151/000154315126000015/uber-20251231.htm
A13: 5 | B13: FY2024 full-year results (prior-year comparison) | C13: Form 8-K (Ex-99.1) — Q4 & FY2024 earnings release | D13: Year ended 12/31/2024 | E13: sec.gov/Archives/edgar/data/1543151/000154315125000004/uberq424earningspressrelea.htm
A14: 6 | B14: FY2023 results (revenue $37.3B, GB $137.9B, adj EBITDA $4.05B, FCF $3.36B) | C14: Uber Q4/FY2023 earnings release + 10-K | D14: Year ended 12/31/2023 | E14: sec.gov / investor.uber.com
A15: 7 | B15: FY2022 results (revenue $31.9B, GB $115.4B, adj EBITDA $1.71B, FCF $0.39B) | C15: Form 8-K (Ex-99.1) — Q4 & FY2022 earnings release | D15: Year ended 12/31/2022 | E15: sec.gov/Archives/edgar/data/1543151/000154315123000004/uberq422earningspressrelea.htm
A16: 8 | B16: FY2021 results (revenue $17.5B, GB $90.4B, adj EBITDA -$0.77B, FCF -$0.74B) | C16: Form 8-K (Ex-99.1) — Q4 & FY2021 earnings release | D16: Year ended 12/31/2021 | E16: sec.gov/Archives/edgar/data/1543151/000154315122000004/uberq421earningspressrelea.htm
A17: 9 | B17: Current share price (~$73), market cap (~$149B), shares out (~2.04B), 52-wk range, analyst ratings | C17: Market data (CNBC / Macrotrends / Robinhood quote pages) | D17: As of ~June 12-13, 2026 | E17: cnbc.com/quotes/UBER ; macrotrends.net/stocks/charts/UBER
A18: 10 | B18: AV / robotaxi competitive context (Waymo expansion, Uber AV partnerships: Wayve, WeRide, Nuro, etc.) | C18: Company news & press (CNBC, Reuters, TipRanks) | D18: May–June 2026 | E18: investor.uber.com ; cnbc.com
A20: Disclaimer
A21: This workbook is an educational portfolio case study demonstrating valuation methodology. It is NOT investment advice, not a recommendation to buy or sell any security, and the author is not a licensed financial advisor. Forward estimates are illustrative assumptions and will differ from actual results.

Sheet Historical Financials
A1: HISTORICAL FINANCIALS (FY2021–FY2025)
A2: All figures US$ millions unless noted. BLUE = reported actuals from SEC filings. BLACK = calculated.
A4: US$ millions | C4: 2021 | D4: 2022 | E4: 2023 | F4: 2024 | G4: 2025
A5: Gross Bookings | C5: 90415 | D5: 115395 | E5: 137865 | F5: 162773 | G5: 193454
A6: % growth YoY | D6: =D5/C5-1 -> 0.27628159 | E6: =E5/D5-1 -> 0.19472247 | F6: =F5/E5-1 -> 0.1806695 | G6: =G5/F5-1 -> 0.18848949
A7: Revenue | C7: 17455 | D7: 31877 | E7: 37281 | F7: 43978 | G7: 52017
A8: % growth YoY | D8: =D7/C7-1 -> 0.8262389 | E8: =E7/D7-1 -> 0.16952662 | F8: =F7/E7-1 -> 0.17963574 | G8: =G7/F7-1 -> 0.18279594
A9: Take rate (Rev / GB) | C9: =C7/C5 -> 0.19305425 | D9: =D7/D5 -> 0.27624247 | E9: =E7/E5 -> 0.27041671 | F9: =F7/F5 -> 0.27017994 | G9: =G7/G5 -> 0.26888563
A10: Adjusted EBITDA | C10: -774 | D10: 1713 | E10: 4052 | F10: 6484 | G10: 8730
A11: Adj. EBITDA margin (% of GB) | C11: =C10/C5 -> -0.0085605265 | D11: =D10/D5 -> 0.014844664 | E11: =E10/E5 -> 0.029391071 | F11: =F10/F5 -> 0.039834616 | G11: =G10/G5 -> 0.045127007
A12: GAAP income from operations | C12: -3832 | D12: -1832 | E12: 1110 | F12: 2799 | G12: 5565
A13: Net income (attributable) | C13: -496 | D13: -9141 | E13: 1887 | F13: 9856 | G13: 10053
A14: Operating cash flow | C14: -445 | D14: 642 | E14: 3585 | F14: 7137 | G14: 10099
A15: Free cash flow | C15: -743 | D15: 390 | E15: 3362 | F15: 6895 | G15: 9763
A16: FCF margin (% of revenue) | C16: =C15/C7 -> -0.0425666 | D16: =D15/D7 -> 0.012234526 | E16: =E15/E7 -> 0.090179984 | F16: =F15/F7 -> 0.15678294 | G16: =G15/G7 -> 0.18768864
A17: FCF / Adj. EBITDA conversion | C17: =IF(C10=0,"-",C15/C10) -> 0.95994832 | D17: =IF(D10=0,"-",D15/D10) -> 0.22767075 | E17: =IF(E10=0,"-",E15/E10) -> 0.82971372 | F17: =IF(F10=0,"-",F15/F10) -> 1.0633868 | G17: =IF(G10=0,"-",G15/G10) -> 1.1183276
A18: Trips (millions) | C18: 6368 | D18: 7637 | E18: 9436 | F18: 11273 | G18: 13567
A19: MAPCs, Q4 (millions) | C19: 118 | D19: 131 | E19: 150 | F19: 171 | G19: 202
A21: Memo: 5-yr CAGR (FY21–FY25)
A22: Gross Bookings CAGR | C22: =(G5/C5)^(1/4)-1 -> 0.20943994
A23: Revenue CAGR | C23: =(G7/C7)^(1/4)-1 -> 0.313882
A24: Adj. EBITDA grew from negative to | C24: =G10 -> 8730
A26: FY2025 GAAP Income Statement detail (US$mm) | G26: Balance sheet @ 12/31/2025 (US$mm)
A27: Revenue | C27: 52017 | G27: Cash & cash equivalents | I27: 7105
A28: Cost of revenue (excl. D&A) | C28: -31338 | G28: Short-term investments | I28: 528
A29: Operations & support | C29: -2854 | G29: Unrestricted cash + ST inv. | I29: =I27+I28 -> 7633
A30: Sales & marketing | C30: -4898 | G30: Long-term debt (net of current) | I30: 10521
A31: Research & development | C31: -3402 | G31: Non-op. equity investments | I31: 9178
A32: General & administrative | C32: -3241 | G32: Total equity | I32: 27918
A33: Depreciation & amortization | C33: -719 | G33: Total assets | I33: 61802
A34: Income from operations | C34: =SUM(C27:C33) -> 5565
A35: Interest expense | C35: -440 | G35: Net debt (debt – unrestricted cash) | I35: =I30-I29 -> 2888
A36: Interest income | C36: 743
A37: Other income (expense), net | C37: -68
A38: Pre-tax income | C38: =C34+SUM(C35:C37) -> 5800
A39: Tax benefit (incl. $5.0B valuation release) | C39: 4346
A40: Loss from equity-method investments | C40: -53
A41: Net income (incl. NCI) | C41: =C38+C39+C40 -> 10093

Sheet Assumptions
A1: ASSUMPTIONS & SCENARIO DRIVERS
A2: BLUE = analyst input (editable). These are illustrative estimates, NOT Uber guidance. Change blue cells to re-run the model.
A4: GLOBAL ASSUMPTIONS (constant across scenarios)
A5: Take rate (Revenue / Gross Bookings) | C5: 0.27 | D5: 2025 actual 26.9%; held ~flat
A6: Depreciation & amortization (% of revenue) | C6: 0.013 | D6: 2025 actual ~1.38% (asset-light)
A7: Shares outstanding (millions, diluted) | C7: 2040 | D7: ~Current diluted share count, mid-2026
A8: Current share price ($) | C8: 73 | D8: Approx. as of ~June 13, 2026
A9: Total debt (US$mm) | C9: 10521 | D9: FY2025 long-term debt, net of current
A10: Unrestricted cash + ST investments (US$mm) | C10: 7633 | D10: FY2025: $7,105 cash + $528 ST inv
A11: Net debt (US$mm) | C11: =C9-C10 -> 2888 | D11: Total debt less unrestricted cash & ST investments
A12: Non-operating equity investments (US$mm) | C12: 9178 | D12: Aurora/Grab/Didi etc. minority stakes
A13: Equity-stake haircut (illiquidity/volatility) | C13: 0.3 | D13: Discount applied to carrying value
A14: Credited stake value (US$mm) | C14: =C12*(1-C13) -> 6424.6 | D14: Carrying value of stakes, less the haircut above
A17: SCENARIO DRIVERS | C17: Bear | D17: Base | E17: Bull
A18: Gross Bookings growth — 2026E | C18: 0.12 | D18: 0.18 | E18: 0.22
A19: Gross Bookings growth — 2027E | C19: 0.09 | D19: 0.16 | E19: 0.2
A20: Gross Bookings growth — 2028E | C20: 0.06 | D20: 0.14 | E20: 0.17
A21: Gross Bookings growth — 2029E | C21: 0.04 | D21: 0.12 | E21: 0.15
A22: Gross Bookings growth — 2030E | C22: 0.03 | D22: 0.11 | E22: 0.13
A23: Adj. EBITDA margin (%GB) — 2026E | C23: 0.043 | D23: 0.048 | E23: 0.05
A24: Adj. EBITDA margin (%GB) — 2027E | C24: 0.042 | D24: 0.052 | E24: 0.056
A25: Adj. EBITDA margin (%GB) — 2028E | C25: 0.042 | D25: 0.056 | E25: 0.062
A26: Adj. EBITDA margin (%GB) — 2029E | C26: 0.043 | D26: 0.06 | E26: 0.068
A27: Adj. EBITDA margin (%GB) — 2030E | C27: 0.045 | D27: 0.063 | E27: 0.072
A28: Stock-based comp (% of revenue) | C28: 0.036 | D28: 0.032 | E28: 0.03
A29: Capex (% of revenue) | C29: 0.012 | D29: 0.008 | E29: 0.007
... A35: Scenario probability weight | C35: 0.25 | D35: 0.5 | E35: 0.25
A36: Probability check (should = 100%) | C36: =SUM(C35:E35) -> 1

Sheet Forecast
A1: 5-YEAR FORECAST — BASE CASE (US$mm)
A2: Drivers link to Assumptions 'Base' column (GREEN). 2025A links to Historical Financials. All else are formulas.
A4: US$ millions | C4: 2025A | D4: 2026E | E4: 2027E | F4: 2028E | G4: 2029E | H4: 2030E
A5: Gross Bookings | C5: ='Historical Financials'!G5 -> 193454 | D5: =C5*(1+D6) -> 228275.72 | E5: =D5*(1+E6) -> 264799.84 | F5: =E5*(1+F6) -> 301871.81 | G5: =F5*(1+G6) -> 338096.43 | H5: =G5*(1+H6) -> 375287.04
A6: GB growth (driver) | D6: =Assumptions!D18 -> 0.18 | E6: =Assumptions!D19 -> 0.16 | F6: =Assumptions!D20 -> 0.14 | G6: =Assumptions!D21 -> 0.12 | H6: =Assumptions!D22 -> 0.11
A7: Revenue | C7: ='Historical Financials'!G7 -> 52017 | D7: =D5*Assumptions!$C$5 -> 61634.444 | E7: =E5*Assumptions!$C$5 -> 71495.956 | F7: =F5*Assumptions!$C$5 -> 81505.389 | G7: =G5*Assumptions!$C$5 -> 91286.036 | H7: =H5*Assumptions!$C$5 -> 101327.5
A8: Adj. EBITDA | C8: ='Historical Financials'!G10 -> 8730 | D8: =D5*Assumptions!D23 -> 10957.235 | E8: =E5*Assumptions!D24 -> 13769.591 | F8: =F5*Assumptions!D25 -> 16904.821 | G8: =G5*Assumptions!D26 -> 20285.786 | H8: =H5*Assumptions!D27 -> 23643.083
A9: Adj. EBITDA margin (%GB) | C9: =C8/C5 -> 0.045127007 | D9: =D8/D5 -> 0.048 | E9: =E8/E5 -> 0.052 | F9: =F8/F5 -> 0.056 | G9: =G8/G5 -> 0.06 | H9: =H8/H5 -> 0.063
A10: Less: stock-based comp | D10: =-D7*Assumptions!$D$28 -> -1972.3022 | E10: =-E7*Assumptions!$D$28 -> -2287.8706 | F10: =-F7*Assumptions!$D$28 -> -2608.1725 | G10: =-G7*Assumptions!$D$28 -> -2921.1532 | H10: =-H7*Assumptions!$D$28 -> -3242.48
A11: Less: D&A | D11: =-D7*Assumptions!$C$6 -> -801.24778 | E11: =-E7*Assumptions!$C$6 -> -929.44742 | F11: =-F7*Assumptions!$C$6 -> -1059.5701 | G11: =-G7*Assumptions!$C$6 -> -1186.7185 | H11: =-H7*Assumptions!$C$6 -> -1317.2575
A12: EBIT (post-SBC) | D12: =D8+D10+D11 -> 8183.6846 | E12: =E8+E10+E11 -> 10552.273 | F12: =F8+F10+F11 -> 13237.079 | G12: =G8+G10+G11 -> 16177.914 | H12: =H8+H10+H11 -> 19083.346
A13: Less: cash taxes | D13: =-D12*Assumptions!$D$31 -> -1718.5738 | E13: =-E12*Assumptions!$D$31 -> -2215.9774 | F13: =-F12*Assumptions!$D$31 -> -2779.7866 | G13: =-G12*Assumptions!$D$31 -> -3397.362 | H13: =-H12*Assumptions!$D$31 -> -4007.5026
A14: NOPAT | D14: =D12+D13 -> 6465.1108 | E14: =E12+E13 -> 8336.296 | F14: =F12+F13 -> 10457.292 | G14: =G12+G13 -> 12780.552 | H14: =H12+H13 -> 15075.843
A15: Plus: D&A | D15: =-D11 -> 801.24778 | E15: =-E11 -> 929.44742 | F15: =-F11 -> 1059.5701 | G15: =-G11 -> 1186.7185 | H15: =-H11 -> 1317.2575
A16: Less: capex | D16: =-D7*Assumptions!$D$29 -> -493.07556 | E16: =-E7*Assumptions!$D$29 -> -571.96764 | F16: =-F7*Assumptions!$D$29 -> -652.04311 | G16: =-G7*Assumptions!$D$29 -> -730.28829 | H16: =-H7*Assumptions!$D$29 -> -810.62
A17: +/- working capital | D17: =D7*Assumptions!$D$30 -> 431.44111 | E17: =E7*Assumptions!$D$30 -> 500.47169 | F17: =F7*Assumptions!$D$30 -> 570.53772 | G17: =G7*Assumptions!$D$30 -> 639.00225 | H17: =H7*Assumptions!$D$30 -> 709.2925
A18: Unlevered free cash flow | C18: ='Historical Financials'!G15 -> 9763 | D18: =D14+D15+D16+D17 -> 7204.7241 | E18: =E14+E15+E16+E17 -> 9194.2475 | F18: =F14+F15+F16+F17 -> 11435.357 | G18: =G14+G15+G16+G17 -> 13875.985 | H18: =H14+H15+H16+H17 -> 16291.773
A19: FCF margin (% revenue) | C19: =C18/C7 -> 0.18768864 | D19: =D18/D7 -> 0.11689444 | E19: =E18/E7 -> 0.12859815 | F19: =F18/F7 -> 0.14030185 | G19: =G18/G7 -> 0.15200556 | H19: =H18/H7 -> 0.16078333
A20: FCF / Adj. EBITDA conversion | D20: =D18/D8 -> 0.65753125 | E20: =E18/E8 -> 0.66772115 | F20: =F18/F8 -> 0.67645536 | G20: =G18/G8 -> 0.684025 | H20: =H18/H8 -> 0.68907143
A22: Note: Adj. EBITDA excludes stock-based comp; this model treats SBC as a real cash/economic cost and deducts it before tax. Reported (company-defined) FCF is higher because it adds back SBC and benefits from favourable working-capital timing.

Sheet Valuation
A1: DCF VALUATION — BASE CASE
A2: Unlevered free-cash-flow DCF off the Base-case forecast. GREEN = links to Forecast / Assumptions.
A4: Discounting of explicit free cash flows (2026E–2030E)
A6: Forecast year | D6: 2026E | E6: 2027E | F6: 2028E | G6: 2029E | H6: 2030E
A7: Unlevered FCF (US$mm) | D7: =Forecast!D18 -> 7204.7241 | E7: =Forecast!E18 -> 9194.2475 | F7: =Forecast!F18 -> 11435.357 | G7: =Forecast!G18 -> 13875.985 | H7: =Forecast!H18 -> 16291.773
A8: Discount period (t) | D8: 1 | E8: 2 | F8: 3 | G8: 4 | H8: 5
A9: Discount factor | D9: =1/(1+$C$12)^D8 -> 0.91324201 | E9: =1/(1+$C$12)^E8 -> 0.83401097 | F9: =1/(1+$C$12)^F8 -> 0.76165385 | G9: =1/(1+$C$12)^G8 -> 0.69557429 | H9: =1/(1+$C$12)^H8 -> 0.63522767
A10: PV of FCF | D10: =D7*D9 -> 6579.6567 | E10: =E7*E9 -> 7668.1032 | F10: =F7*F9 -> 8709.7837 | G10: =G7*G9 -> 9651.7782 | H10: =H7*H9 -> 10348.985
A12: WACC | C12: =Assumptions!$D$32 -> 0.095
A13: Terminal growth rate (g) | C13: =Assumptions!$D$33 -> 0.03
A15: Sum PV of explicit FCF | C15: =SUM(D10:H10) -> 42958.307
A16: Terminal value (Gordon growth) | C16: =H7*(1+C13)/(C12-C13) -> 258161.94
A17: PV of terminal value | C17: =C16*H9 -> 163991.61
A18: Memo: terminal value as % of EV | C18: =C17/C20 -> 0.79242172
A19: Memo: TV via exit EV/EBITDA (cross-check) | C19: =Forecast!H8*Assumptions!$D$34*H9 -> 195243.63
A20: ENTERPRISE VALUE | C20: =C15+C17 -> 206949.92
A21: Less: net debt | C21: =-Assumptions!$C$11 -> -2888
A22: Plus: credited equity investments | C22: =Assumptions!$C$14 -> 6424.6
A23: EQUITY VALUE | C23: =C20+C21+C22 -> 210486.52
A24: Shares outstanding (mm) | C24: =Assumptions!$C$7 -> 2040
A25: IMPLIED VALUE PER SHARE | C25: =C23/C24 -> 103.17966
A26: Current share price | C26: =Assumptions!$C$8 -> 73
A27: Implied upside / (downside) | C27: =C25/C26-1 -> 0.41342007
A29: Implied-multiple cross-checks
A30: Implied EV / 2026E Adj. EBITDA | C30: =C20/Forecast!D8 -> 18.887057
A31: Implied EV / 2030E Adj. EBITDA | C31: =C20/Forecast!H8 -> 8.7530849
A32: Implied EV / 2026E revenue | C32: =C20/Forecast!D7 -> 3.3576991
A33: Implied equity value / FY25 FCF (reported) | C33: =C23/'Historical Financials'!G15 -> 21.559614
A35: Interpretation: the base case discounts Uber's unlevered FCF at a ~9.5% WACC with 3.0% terminal growth. Because terminal value is a large share of EV (typical for a compounding platform), the output is sensitive to WACC and terminal assumptions — see the Sensitivity Tables and Scenario Analysis tabs.

Sheet Scenario Analysis
A1: SCENARIO ANALYSIS & DOWNSIDE STRESS TEST
A2: Bull / Base / Bear each re-run the full DCF with its own growth, margin, FCF-conversion, WACC and terminal assumptions.
A4: SCENARIO COMPARISON (per-share outcomes)
A5: Metric | C5: Bear | D5: Base | E5: Bull
A6: 2030E Gross Bookings (US$mm) | C6: =H21 -> 268162.88 | D6: =H35 -> 375287.04 | E6: =H49 -> 430606.85
A7: 2030E Adj. EBITDA (US$mm) | C7: =H22 -> 12067.33 | D7: =H36 -> 23643.083 | E7: =H50 -> 31003.693
A8: Enterprise value (US$mm) | C8: =C29 -> 64101.818 | D8: =C43 -> 206949.92 | E8: =C57 -> 330239.32
A9: Equity value (US$mm) | C9: =C30 -> 67638.418 | D9: =C44 -> 210486.52 | E9: =C58 -> 333775.92
A10: Implied value per share ($) | C10: =C31 -> 33.156087 | D10: =C45 -> 103.17966 | E10: =C59 -> 163.61565
A11: Upside / (downside) vs current | C11: =C32 -> -0.54580703 | D11: =C46 -> 0.41342007 | E11: =C60 -> 1.2413102
A12: Terminal value (PV, US$mm) | C12: =C28 -> 43720.468 | D12: =C42 -> 163991.61 | E12: =C56 -> 274345.06
A13: Probability weight | C13: =Assumptions!C$35 -> 0.25 | D13: =Assumptions!D$35 -> 0.5 | E13: =Assumptions!E$35 -> 0.25
A14: Probability-weighted fair value ($) | C14: =C10*C13+D10*D13+E10*E13 -> 100.78277 | D14: Weighted upside: | E14: =C14/Assumptions!$C$8-1 -> 0.38058583
A16: Read-through: the spread between the bear (~stress) and bull cases is wide because Uber's value hinges on whether its demand-aggregation model captures or is disrupted by autonomous vehicles. The bear case deliberately stacks slower bookings growth, margin stalling, weaker FCF conversion, a higher WACC and a lower terminal growth rate to size 'how much breaks if the thesis breaks.'
A20: BEAR CASE — downside stress test | D20: 2026E | E20: 2027E | F20: 2028E | G20: 2029E | H20: 2030E
A21: Gross Bookings | D21: ='Historical Financials'!$G$5*(1+Assumptions!C$18) -> 216668.48 | E21: =D21*(1+Assumptions!C$19) -> 236168.64 | F21: =E21*(1+Assumptions!C$20) -> 250338.76 | G21: =F21*(1+Assumptions!C$21) -> 260352.31 | H21: =G21*(1+Assumptions!C$22) -> 268162.88
A22: Adj. EBITDA | D22: =D21*Assumptions!C$23 -> 9316.7446 | E22: =E21*Assumptions!C$24 -> 9919.083 | F22: =F21*Assumptions!C$25 -> 10514.228 | G22: =G21*Assumptions!C$26 -> 11195.149 | H22: =H21*Assumptions!C$27 -> 12067.33
A23: Unlevered FCF | D23: =(D22-(D21*Assumptions!$C$5)*(Assumptions!C$28+Assumptions!$C$6))*(1-Assumptions!C$31)+(D21*Assumptions!$C$5)*(Assumptions!$C$6-Assumptions!C$29+Assumptions!C$30) -> 4914.1711 | E23: =(E22-(E21*Assumptions!$C$5)*(Assumptions!C$28+Assumptions!$C$6))*(1-Assumptions!C$31)+(E21*Assumptions!$C$5)*(Assumptions!$C$6-Assumptions!C$29+Assumptions!C$30) -> 5172.235 | F23: =(F22-(F21*Assumptions!$C$5)*(Assumptions!C$28+Assumptions!$C$6))*(1-Assumptions!C$31)+(F21*Assumptions!$C$5)*(Assumptions!$C$6-Assumptions!C$29+Assumptions!C$30) -> 5482.5691 | G23: =(G22-(G21*Assumptions!$C$5)*(Assumptions!C$28+Assumptions!$C$6))*(1-Assumptions!C$31)+(G21*Assumptions!$C$5)*(Assumptions!$C$6-Assumptions!C$29+Assumptions!C$30) -> 5904.9467 | H23: =(H22-(H21*Assumptions!$C$5)*(Assumptions!C$28+Assumptions!$C$6))*(1-Assumptions!C$31)+(H21*Assumptions!$C$5)*(Assumptions!$C$6-Assumptions!C$29+Assumptions!C$30) -> 6500.4291
A24: Discount factor | D24: =1/(1+Assumptions!C$32)^1 -> 0.9009009 | E24: =1/(1+Assumptions!C$32)^2 -> 0.81162243 | F24: =1/(1+Assumptions!C$32)^3 -> 0.73119138 | G24: =1/(1+Assumptions!C$32)^4 -> 0.65873097 | H24: =1/(1+Assumptions!C$32)^5 -> 0.59345133
A25: PV of FCF | D25: =D23*D24 -> 4427.1812 | E25: =E23*E24 -> 4197.9019 | F25: =F23*F24 -> 4008.8073 | G25: =G23*G24 -> 3889.7713 | H25: =H23*H24 -> 3857.6883
A27: Sum PV explicit FCF | C27: =SUM(D25:H25) -> 20381.35
A28: PV of terminal value | C28: =(H23*(1+Assumptions!C$33)/(Assumptions!C$32-Assumptions!C$33))*H24 -> 43720.468
A29: Enterprise value | C29: =C27+C28 -> 64101.818
A30: Equity value | C30: =C29-Assumptions!$C$11+Assumptions!$C$14 -> 67638.418
A31: Implied value / share | C31: =C30/Assumptions!$C$7 -> 33.156087
A32: Upside / (downside) | C32: =C31/Assumptions!$C$8-1 -> -0.54580703
A34: BASE CASE | D34: 2026E | E34: 2027E | F34: 2028E | G34: 2029E | H34: 2030E
A35: Gross Bookings | D35: ='Historical Financials'!$G$5*(1+Assumptions!D$18) -> 228275.72 | E35: =D35*(1+Assumptions!D$19) -> 264799.84 | F35: =E35*(1+Assumptions!D$20) -> 301871.81 | G35: =F35*(1+Assumptions!D$21) -> 338096.43 | H35: =G35*(1+Assumptions!D$22) -> 375287.04
A36: Adj. EBITDA | D36: =D35*Assumptions!D$23 -> 10957.235 | E36: =E35*Assumptions!D$24 -> 13769.591 | F36: =F35*Assumptions!D$25 -> 16904.821 | G36: =G35*Assumptions!D$26 -> 20285.786 | H36: =H35*Assumptions!D$27 -> 23643.083
A37: Unlevered FCF | D37: =(D36-(D35*Assumptions!$C$5)*(Assumptions!D$28+Assumptions!$C$6))*(1-Assumptions!D$31)+(D35*Assumptions!$C$5)*(Assumptions!$C$6-Assumptions!D$29+Assumptions!D$30) -> 7204.7241 | E37: =(E36-(E35*Assumptions!$C$5)*(Assumptions!D$28+Assumptions!$C$6))*(1-Assumptions!D$31)+(E35*Assumptions!$C$5)*(Assumptions!$C$6-Assumptions!D$29+Assumptions!D$30) -> 9194.2475 | F37: =(F36-(F35*Assumptions!$C$5)*(Assumptions!D$28+Assumptions!$C$6))*(1-Assumptions!D$31)+(F35*Assumptions!$C$5)*(Assumptions!$C$6-Assumptions!D$29+Assumptions!D$30) -> 11435.357 | G37: =(G36-(G35*Assumptions!$C$5)*(Assumptions!D$28+Assumptions!$C$6))*(1-Assumptions!D$31)+(G35*Assumptions!$C$5)*(Assumptions!$C$6-Assumptions!D$29+Assumptions!D$30) -> 13875.985 | H37: =(H36-(H35*Assumptions!$C$5)*(Assumptions!D$28+Assumptions!$C$6))*(1-Assumptions!D$31)+(H35*Assumptions!$C$5)*(Assumptions!$C$6-Assumptions!D$29+Assumptions!D$30) -> 16291.773
A38: Discount factor | D38: =1/(1+Assumptions!D$32)^1 -> 0.91324201 | E38: =1/(1+Assumptions!D$32)^2 -> 0.83401097 | F38: =1/(1+Assumptions!D$32)^3 -> 0.76165385 | G38: =1/(1+Assumptions!D$32)^4 -> 0.69557429 | H38: =1/(1+Assumptions!D$32)^5 -> 0.63522767
A39: PV of FCF | D39: =D37*D38 -> 6579.6567 | E39: =E37*E38 -> 7668.1032 | F39: =F37*F38 -> 8709.7837 | G39: =G37*G38 -> 9651.7782 | H39: =H37*H38 -> 10348.985
A41: Sum PV explicit FCF | C41: =SUM(D39:H39) -> 42958.307
A42: PV of terminal value | C42: =(H37*(1+Assumptions!D$33)/(Assumptions!D$32-Assumptions!D$33))*H38 -> 163991.61
A43: Enterprise value | C43: =C41+C42 -> 206949.92
A44: Equity value | C44: =C43-Assumptions!$C$11+Assumptions!$C$14 -> 210486.52
A45: Implied value / share | C45: =C44/Assumptions!$C$7 -> 103.17966
A46: Upside / (downside) | C46: =C45/Assumptions!$C$8-1 -> 0.41342007
A48: BULL CASE | D48: 2026E | E48: 2027E | F48: 2028E | G48: 2029E | H48: 2030E
A49: Gross Bookings | D49: ='Historical Financials'!$G$5*(1+Assumptions!E$18) -> 236013.88 | E49: =D49*(1+Assumptions!E$19) -> 283216.66 | F49: =E49*(1+Assumptions!E$20) -> 331363.49 | G49: =F49*(1+Assumptions!E$21) -> 381068.01 | H49: =G49*(1+Assumptions!E$22) -> 430606.85
...

Sheet Sensitivity Tables
A1: VALUATION SENSITIVITY TABLES
A2: Implied value per share ($) under paired assumption shocks. Cells are live formulas off the Forecast / Scenario tabs. 'n/m' where WACC ≤ g.
A4: Table 1 — Base-case implied share price: WACC (rows) × terminal growth g (columns)
A5: WACC \ term. g → | B5: 0.02 | C5: 0.025 | D5: 0.03 | E5: 0.035 | F5: 0.04
A6: 0.085 | B6: =IF($A$6<=B$5,"n/m",((Forecast!D18/(1+$A$6)^1+Forecast!E18/(1+$A$6)^2+Forecast!F18/(1+$A$6)^3+Forecast!G18/(1+$A$6)^4+Forecast!H18/(1+$A$6)^5)+((Forecast!$H$18*(1+B$5)/($A$6-B$5))/(1+$A$6)^5)-Assumptions!$C$11+Assumptions!$C$14)/Assumptions!$C$7) -> 106.76946 | C6: =IF($A$6<=C$5,"n/m",((Forecast!D18/(1+$A$6)^1+Forecast!E18/(1+$A$6)^2+Forecast!F18/(1+$A$6)^3+Forecast!G18/(1+$A$6)^4+Forecast!H18/(1+$A$6)^5)+((Forecast!$H$18*(1+C$5)/($A$6-C$5))/(1+$A$6)^5)-Assumptions!$C$11+Assumptions!$C$14)/Assumptions!$C$7) -> 114.15742 | D6: =IF($A$6<=D$5,"n/m",((Forecast!D18/(1+$A$6)^1+Forecast!E18/(1+$A$6)^2+Forecast!F18/(1+$A$6)^3+Forecast!G18/(1+$A$6)^4+Forecast!H18/(1+$A$6)^5)+((Forecast!$H$18*(1+D$5)/($A$6-D$5))/(1+$A$6)^5)-Assumptions!$C$11+Assumptions!$C$14)/Assumptions!$C$7) -> 122.88864 | E6: =IF($A$6<=E$5,"n/m",((Forecast!D18/(1+$A$6)^1+Forecast!E18/(1+$A$6)^2+Forecast!F18/(1+$A$6)^3+Forecast!G18/(1+$A$6)^4+Forecast!H18/(1+$A$6)^5)+((Forecast!$H$18*(1+E$5)/($A$6-E$5))/(1+$A$6)^5)-Assumptions!$C$11+Assumptions!$C$14)/Assumptions!$C$7) -> 133.36612 | F6: =IF($A$6<=F$5,"n/m",((Forecast!D18/(1+$A$6)^1+Forecast!E18/(1+$A$6)^2+Forecast!F18/(1+$A$6)^3+Forecast!G18/(1+$A$6)^4+Forecast!H18/(1+$A$6)^5)+((Forecast!$H$18*(1+F$5)/($A$6-F$5))/(1+$A$6)^5)-Assumptions!$C$11+Assumptions!$C$14)/Assumptions!$C$7) -> 146.17192
A7: 0.09 | B7: =IF($A$7<=B$5,"n/m",((Forecast!D18/(1+$A$7)^1+Forecast!E18/(1+$A$7)^2+Forecast!F18/(1+$A$7)^3+Forecast!G18/(1+$A$7)^4+Forecast!H18/(1+$A$7)^5)+((Forecast!$H$18*(1+B$5)/($A$7-B$5))/(1+$A$7)^5)-Assumptions!$C$11+Assumptions!$C$14)/Assumptions!$C$7) -> 98.737234 | C7: =IF($A$7<=C$5,"n/m",((Forecast!D18/(1+$A$7)^1+Forecast!E18/(1+$A$7)^2+Forecast!F18/(1+$A$7)^3+Forecast!G18/(1+$A$7)^4+Forecast!H18/(1+$A$7)^5)+((Forecast!$H$18*(1+C$5)/($A$7-C$5))/(1+$A$7)^5)-Assumptions!$C$11+Assumptions!$C$14)/Assumptions!$C$7) -> 104.95438 | D7: =IF($A$7<=D$5,"n/m",((Forecast!D18/(1+$A$7)^1+Forecast!E18/(1+$A$7)^2+Forecast!F18/(1+$A$7)^3+Forecast!G18/(1+$A$7)^4+Forecast!H18/(1+$A$7)^5)+((Forecast!$H$18*(1+D$5)/($A$7-D$5))/(1+$A$7)^5)-Assumptions!$C$11+Assumptions!$C$14)/Assumptions!$C$7) -> 112.20771 | E7: =IF($A$7<=E$5,"n/m",((Forecast!D18/(1+$A$7)^1+Forecast!E18/(1+$A$7)^2+Forecast!F18/(1+$A$7)^3+Forecast!G18/(1+$A$7)^4+Forecast!H18/(1+$A$7)^5)+((Forecast!$H$18*(1+E$5)/($A$7-E$5))/(1+$A$7)^5)-Assumptions!$C$11+Assumptions!$C$14)/Assumptions!$C$7) -> 120.77983 | F7: =IF($A$7<=F$5,"n/m",((Forecast!D18/(1+$A$7)^1+Forecast!E18/(1+$A$7)^2+Forecast!F18/(1+$A$7)^3+Forecast!G18/(1+$A$7)^4+Forecast!H18/(1+$A$7)^5)+((Forecast!$H$18*(1+F$5)/($A$7-F$5))/(1+$A$7)^5)-Assumptions!$C$11+Assumptions!$C$14)/Assumptions!$C$7) -> 131.06637
A8: 0.095 | B8: =IF($A$8<=B$5,"n/m",((Forecast!D18/(1+$A$8)^1+Forecast!E18/(1+$A$8)^2+Forecast!F18/(1+$A$8)^3+Forecast!G18/(1+$A$8)^4+Forecast!H18/(1+$A$8)^5)+((Forecast!$H$18*(1+B$5)/($A$8-B$5))/(1+$A$8)^5)-Assumptions!$C$11+Assumptions!$C$14)/Assumptions!$C$7) -> 91.784855 | C8: =IF($A$8<=C$5,"n/m",((Forecast!D18/(1+$A$8)^1+Forecast!E18/(1+$A$8)^2+Forecast!F18/(1+$A$8)^3+Forecast!G18/(1+$A$8)^4+Forecast!H18/(1+$A$8)^5)+((Forecast!$H$18*(1+C$5)/($A$8-C$5))/(1+$A$8)^5)-Assumptions!$C$11+Assumptions!$C$14)/Assumptions!$C$7) -> 97.075302 | D8: =IF($A$8<=D$5,"n/m",((Forecast!D18/(1+$A$8)^1+Forecast!E18/(1+$A$8)^2+Forecast!F18/(1+$A$8)^3+Forecast!G18/(1+$A$8)^4+Forecast!H18/(1+$A$8)^5)+((Forecast!$H$18*(1+D$5)/($A$8-D$5))/(1+$A$8)^5)-Assumptions!$C$11+Assumptions!$C$14)/Assumptions!$C$7) -> 103.17966 | E8: =IF($A$8<=E$5,"n/m",((Forecast!D18/(1+$A$8)^1+Forecast!E18/(1+$A$8)^2+Forecast!F18/(1+$A$8)^3+Forecast!G18/(1+$A$8)^4+Forecast!H18/(1+$A$8)^5)+((Forecast!$H$18*(1+E$5)/($A$8-E$5))/(1+$A$8)^5)-Assumptions!$C$11+Assumptions!$C$14)/Assumptions!$C$7) -> 110.30142 | F8: =IF($A$8<=F$5,"n/m",((Forecast!D18/(1+$A$8)^1+Forecast!E18/(1+$A$8)^2+Forecast!F18/(1+$A$8)^3+Forecast!G18/(1+$A$8)^4+Forecast!H18/(1+$A$8)^5)+((Forecast!$H$18*(1+F$5)/($A$8-F$5))/(1+$A$8)^5)-Assumptions!$C$11+Assumptions!$C$14)/Assumptions!$C$7) -> 118.71804
A9: 0.1 | B9: =IF($A$9<=B$5,"n/m",((Forecast!D18/(1+$A$9)^1+Forecast!E18/(1+$A$9)^2+Forecast!F18/(1+$A$9)^3+Forecast!G18/(1+$A$9)^4+Forecast!H18/(1+$A$9)^5)+((Forecast!$H$18*(1+B$5)/($A$9-B$5))/(1+$A$9)^5)-Assumptions!$C$11+Assumptions!$C$14)/Assumptions!$C$7) -> 85.709653 | C9: =IF($A$9<=C$5,"n/m",((Forecast!D18/(1+$A$9)^1+Forecast!E18/(1+$A$9)^2+Forecast!F18/(1+$A$9)^3+Forecast!G18/(1+$A$9)^4+Forecast!H18/(1+$A$9)^5)+((Forecast!$H$18*(1+C$5)/($A$9-C$5))/(1+$A$9)^5)-Assumptions!$C$11+Assumptions!$C$14)/Assumptions!$C$7) -> 90.2552 | D9: =IF($A$9<=D$5,"n/m",((Forecast!D18/(1+$A$9)^1+Forecast!E18/(1+$A$9)^2+Forecast!F18/(1+$A$9)^3+Forecast!G18/(1+$A$9)^4+Forecast!H18/(1+$A$9)^5)+((Forecast!$H$18*(1+D$5)/($A$9-D$5))/(1+$A$9)^5)-Assumptions!$C$11+Assumptions!$C$14)/Assumptions!$C$7) -> 95.450112 | E9: =IF($A$9<=E$5,"n/m",((Forecast!D18/(1+$A$9)^1+Forecast!E18/(1+$A$9)^2+Forecast!F18/(1+$A$9)^3+Forecast!G18/(1+$A$9)^4+Forecast!H18/(1+$A$9)^5)+((Forecast!$H$18*(1+E$5)/($A$9-E$5))/(1+$A$9)^5)-Assumptions!$C$11+Assumptions!$C$14)/Assumptions!$C$7) -> 101.44424 | F9: =IF($A$9<=F$5,"n/m",((Forecast!D18/(1+$A$9)^1+Forecast!E18/(1+$A$9)^2+Forecast!F18/(1+$A$9)^3+Forecast!G18/(1+$A$9)^4+Forecast!H18/(1+$A$9)^5)+((Forecast!$H$18*(1+F$5)/($A$9-F$5))/(1+$A$9)^5)-Assumptions!$C$11+Assumptions!$C$14)/Assumptions!$C$7) -> 108.43739
A10: 0.105 | B10: =IF($A$10<=B$5,"n/m",((Forecast!D18/(1+$A$10)^1+Forecast!E18/(1+$A$10)^2+Forecast!F18/(1+$A$10)^3+Forecast!G18/(1+$A$10)^4+Forecast!H18/(1+$A$10)^5)+((Forecast!$H$18*(1+B$5)/($A$10-B$5))/(1+$A$10)^5)-Assumptions!$C$11+Assumptions!$C$14)/Assumptions!$C$7) -> 80.356653 | C10: =IF($A$10<=C$5,"n/m",((Forecast!D18/(1+$A$10)^1+Forecast!E18/(1+$A$10)^2+Forecast!F18/(1+$A$10)^3+Forecast!G18/(1+$A$10)^4+Forecast!H18/(1+$A$10)^5)+((Forecast!$H$18*(1+C$5)/($A$10-C$5))/(1+$A$10)^5)-Assumptions!$C$11+Assumptions!$C$14)/Assumptions!$C$7) -> 84.295328 | D10: =IF($A$10<=D$5,"n/m",((Forecast!D18/(1+$A$10)^1+Forecast!E18/(1+$A$10)^2+Forecast!F18/(1+$A$10)^3+Forecast!G18/(1+$A$10)^4+Forecast!H18/(1+$A$10)^5)+((Forecast!$H$18*(1+D$5)/($A$10-D$5))/(1+$A$10)^5)-Assumptions!$C$11+Assumptions!$C$14)/Assumptions!$C$7) -> 88.75916 | E10: =IF($A$10<=E$5,"n/m",((Forecast!D18/(1+$A$10)^1+Forecast!E18/(1+$A$10)^2+Forecast!F18/(1+$A$10)^3+Forecast!G18/(1+$A$10)^4+Forecast!H18/(1+$A$10)^5)+((Forecast!$H$18*(1+E$5)/($A$10-E$5))/(1+$A$10)^5)-Assumptions!$C$11+Assumptions!$C$14)/Assumptions!$C$7) -> 93.860682 | F10: =IF($A$10<=F$5,"n/m",((Forecast!D18/(1+$A$10)^1+Forecast!E18/(1+$A$10)^2+Forecast!F18/(1+$A$10)^3+Forecast!G18/(1+$A$10)^4+Forecast!H18/(1+$A$10)^5)+((Forecast!$H$18*(1+F$5)/($A$10-F$5))/(1+$A$10)^5)-Assumptions!$C$11+Assumptions!$C$14)/Assumptions!$C$7) -> 99.747054
A11: Base point: WACC 9.5%, g 3.0% (highlighted). Terminal value is a large share of EV, so the price is most sensitive to this pair.
A14: Table 2 — Implied share price: Adj. EBITDA margin %GB (rows) × uniform GB growth (columns)
A15: Holds WACC, terminal g, tax, SBC, capex & WC at base; applies one constant margin & growth for 2026–2030E.
A16: margin \ GB growth → | B16: 0.08 | C16: 0.11 | D16: 0.14 | E16: 0.17 | F16: 0.2
A17: 0.045 | B17: =(('Historical Financials'!$G$5*(($A$17-Assumptions!$C$5*(Assumptions!$D$28+Assumptions!$C$6))*(1-Assumptions!$D$31)+Assumptions!$C$5*(Assumptions!$C$6-Assumptions!$D$29+Assumptions!$D$30))*(((1+B$16)/(1+Assumptions!$D$32))+((1+B$16)/(1+Assumptions!$D$32))^2+((1+B$16)/(1+Assumptions!$D$32))^3+((1+B$16)/(1+Assumptions!$D$32))^4+((1+B$16)/(1+Assumptions!$D$32))^5))+(('Historical Financials'!$G$5*(1+B$16)^5*(($A$17-Assumptions!$C$5*(Assumptions!$D$28+Assumptions!$C$6))*(1-Assumptions!$D$31)+Assumptions!$C$5*(Assumptions!$C$6-Assumptions!$D$29+Assumptions!$D$30))*(1+Assumptions!$D$33)/(Assumptions!$D$32-Assumptions!$D$33))/(1+Assumptions!$D$32)^5)-Assumptions!$C$11+Assumptions!$C$14)/Assumptions!$C$7 -> 55.958956 | C17: =(('Historical Financials'!$G$5*(($A$17-Assumptions!$C$5*(Assumptions!$D$28+Assumptions!$C$6))*(1-Assumptions!$D$31)+Assumptions!$C$5*(Assumptions!$C$6-Assumptions!$D$29+Assumptions!$D$30))*(((1+C$16)/(1+Assumptions!$D$32))+((1+C$16)/(1+Assumptions!$D$32))^2+((1+C$16)/(1+Assumptions!$D$32))^3+((1+C$16)/(1+Assumptions!$D$32))^4+((1+C$16)/(1+Assumptions!$D$32))^5))+(('Historical Financials'!$G$5*(1+C$16)^5*(($A$17-Assumptions!$C$5*(Assumptions!$D$28+Assumptions!$C$6))*(1-Assumptions!$D$31)+Assumptions!$C$5*(Assumptions!$C$6-Assumptions!$D$29+Assumptions!$D$30))*(1+Assumptions!$D$33)/(Assumptions!$D$32-Assumptions!$D$33))/(1+Assumptions!$D$32)^5)-Assumptions!$C$11+Assumptions!$C$14)/Assumptions!$C$7 -> 63.108097 | D17: =(('Historical Financials'!$G$5*(($A$17-Assumptions!$C$5*(Assumptions!$D$28+Assumptions!$C$6))*(1-Assumptions!$D$31)+Assumptions!$C$5*(Assumptions!$C$6-Assumptions!$D$29+Assumptions!$D$30))*(((1+D$16)/(1+Assumptions!$D$32))+((1+D$16)/(1+Assumptions!$D$32))^2+((1+D$16)/(1+Assumptions!$D$32))^3+((1+D$16)/(1+Assumptions!$D$32))^4+((1+D$16)/(1+Assumptions!$D$32))^5))+(('Historical Financials'!$G$5*(1+D$16)^5*(($A$17-Assumptions!$C$5*(Assumptions!$D$28+Assumptions!$C$6))*(1-Assumptions!$D$31)+Assumptions!$C$5*(Assumptions!$C$6-Assumptions!$D$29+Assumptions!$D$30))*(1+Assumptions!$D$33)/(Assumptions!$D$32-Assumptions!$D$33))/(1+Assumptions!$D$32)^5)-Assumptions!$C$11+Assumptions!$C$14)/Assumptions!$C$7 -> 71.029171 | E17: =(('Historical Financials'!$G$5*(($A$17-Assumptions!$C$5*(Assumptions!$D$28+Assumptions!$C$6))*(1-Assumptions!$D$31)+Assumptions!$C$5*(Assumptions!$C$6-Assumptions!$D$29+Assumptions!$D$30))*(((1+E$16)/(1+Assumptions!$D$32))+((1+E$16)/(1+Assumptions!$D$32))^2+((1+E$16)/(1+Assumptions!$D$32))^3+((1+E$16)/(1+Assumptions!$D$32))^4+((1+E$16)/(1+Assumptions!$D$32))^5))+(('Historical Financials'!$G$5*(1+E$16)^5*(($A$17-Assumptions!$C$5*(Assumptions!$D$28+Assumptions!$C$6))*(1-Assumptions!$D$31)+Assumptions!$C$5*(Assumptions!$C$6-Assumptions!$D$29+Assumptions!$D$30))*(1+Assumptions!$D$33)/(Assumptions!$D$32-Assumptions!$D$33))/(1+Assumptions!$D$32)^5)-Assumptions!$C$11+Assumptions!$C$14)/Assumptions!$C$7 -> 79.784673 | F17: =(('Historical Financials'!$G$5*(($A$17-Assumptions!$C$5*(Assumptions!$D$28+Assumptions!$C$6))*(1-Assumptions!$D$31)+Assumptions!$C$5*(Assumptions!$C$6-Assumptions!$D$29+Assumptions!$D$30))*(((1+F$16)/(1+Assumptions!$D$32))+((1+F$16)/(1+Assumptions!$D$32))^2+((1+F$16)/(1+Assumptions!$D$32))^3+((1+F$16)/(1+Assumptions!$D$32))^4+((1+F$16)/(1+Assumptions!$D$32))^5))+(('Historical Financials'!$G$5*(1+F$16)^5*(($A$17-Assumptions!$C$5*(Assumptions!$D$28+Assumptions!$C$6))*(1-Assumptions!$D$31)+Assumptions!$C$5*(Assumptions!$C$6-Assumptions!$D$29+Assumptions!$D$30))*(1+Assumptions!$D$33)/(Assumptions!$D$32-Assumptions!$D$33))/(1+Assumptions!$D$32)^5)-Assumptions!$C$11+Assumptions!$C$14)/Assumptions!$C$7 -> 89.440415
A18: 0.05 | B18: =(('Historical Financials'!$G$5*(($A$18-Assumptions!$C$5*(Assumptions!$D$28+Assumptions!$C$6))*(1-Assumptions!$D$31)+Assumptions!$C$5*(Assumptions!$C$6-Assumptions!$D$29+Assumptions!$D$30))*(((1+B$16)/(1+Assumptions!$D$32))+((1+B$16)/(1+Assumptions!$D$32))^2+((1+B$16)/(1+Assumptions!$D$32))^3+((1+B$16)/(1+Assumptions!$D$32))^4+((1+B$16)/(1+Assumptions!$D$32))^5))+(('Historical Financials'!$G$5*(1+B$16)^5*(($A$18-Assumptions!$C$5*(Assumptions!$D$28+Assumptions!$C$6))*(1-Assumptions!$D$31)+Assumptions!$C$5*(Assumptions!$C$6-Assumptions!$D$29+Assumptions!$D$30))*(1+Assumptions!$D$33)/(Assumptions!$D$32-Assumptions!$D$33))/(1+Assumptions!$D$32)^5)-Assumptions!$C$11+Assumptions!$C$14)/Assumptions!$C$7 -> 63.296368 | C18: =(('Historical Financials'!$G$5*(($A$18-Assumptions!$C$5*(Assumptions!$D$28+Assumptions!$C$6))*(1-Assumptions!$D$31)+Assumptions!$C$5*(Assumptions!$C$6-Assumptions!$D$29+Assumptions!$D$30))*(((1+C$16)/(1+Assumptions!$D$32))+((1+C$16)/(1+Assumptions!$D$32))^2+((1+C$16)/(1+Assumptions!$D$32))^3+((1+C$16)/(1+Assumptions!$D$32))^4+((1+C$16)/(1+Assumptions!$D$32))^5))+(('Historical Financials'!$G$5*(1+C$16)^5*(($A$18-Assumptions!$C$5*(Assumptions!$D$28+Assumptions!$C$6))*(1-Assumptions!$D$31)+Assumptions!$C$5*(Assumptions!$C$6-Assumptions!$D$29+Assumptions!$D$30))*(1+Assumptions!$D$33)/(Assumptions!$D$32-Assumptions!$D$33))/(1+Assumptions!$D$32)^5)-Assumptions!$C$11+Assumptions!$C$14)/Assumptions!$C$7 -> 71.412883 | D18: =(('Historical Financials'!$G$5*(($A$18-Assumptions!$C$5*(Assumptions!$D$28+Assumptions!$C$6))*(1-Assumptions!$D$31)+Assumptions!$C$5*(Assumptions!$C$6-Assumptions!$D$29+Assumptions!$D$30))*(((1+D$16)/(1+Assumptions!$D$32))+((1+D$16)/(1+Assumptions!$D$32))^2+((1+D$16)/(1+Assumptions!$D$32))^3+((1+D$16)/(1+Assumptions!$D$32))^4+((1+D$16)/(1+Assumptions!$D$32))^5))+(('Historical Financials'!$G$5*(1+D$16)^5*(($A$18-Assumptions!$C$5*(Assumptions!$D$28+Assumptions!$C$6))*(1-Assumptions!$D$31)+Assumptions!$C$5*(Assumptions!$C$6-Assumptions!$D$29+Assumptions!$D$30))*(1+Assumptions!$D$33)/(Assumptions!$D$32-Assumptions!$D$33))/(1+Assumptions!$D$32)^5)-Assumptions!$C$11+Assumptions!$C$14)/Assumptions!$C$7 -> 80.405784 | E18: =(('Historical Financials'!$G$5*(($A$18-Assumptions!$C$5*(Assumptions!$D$28+Assumptions!$C$6))*(1-Assumptions!$D$31)+Assumptions!$C$5*(Assumptions!$C$6-Assumptions!$D$29+Assumptions!$D$30))*(((1+E$16)/(1+Assumptions!$D$32))+((1+E$16)/(1+Assumptions!$D$32))^2+((1+E$16)/(1+Assumptions!$D$32))^3+((1+E$16)/(1+Assumptions!$D$32))^4+((1+E$16)/(1+Assumptions!$D$32))^5))+(('Historical Financials'!$G$5*(1+E$16)^5*(($A$18-Assumptions!$C$5*(Assumptions!$D$28+Assumptions!$C$6))*(1-Assumptions!$D$31)+Assumptions!$C$5*(Assumptions!$C$6-Assumptions!$D$29+Assumptions!$D$30))*(1+Assumptions!$D$33)/(Assumptions!$D$32-Assumptions!$D$33))/(1+Assumptions!$D$32)^5)-Assumptions!$C$11+Assumptions!$C$14)/Assumptions!$C$7 -> 90.346022 | F18: =(('Historical Financials'!$G$5*(($A$18-Assumptions!$C$5*(Assumptions!$D$28+Assumptions!$C$6))*(1-Assumptions!$D$31)+Assumptions!$C$5*(Assumptions!$C$6-Assumptions!$D$29+Assumptions!$D$30))*(((1+F$16)/(1+Assumptions!$D$32))+((1+F$16)/(1+Assumptions!$D$32))^2+((1+F$16)/(1+Assumptions!$D$32))^3+((1+F$16)/(1+Assumptions!$D$32))^4+((1+F$16)/(1+Assumptions!$D$32))^5))+(('Historical Financials'!$G$5*(1+F$16)^5*(($A$18-Assumptions!$C$5*(Assumptions!$D$28+Assumptions!$C$6))*(1-Assumptions!$D$31)+Assumptions!$C$5*(Assumptions!$C$6-Assumptions!$D$29+Assumptions!$D$30))*(1+Assumptions!$D$33)/(Assumptions!$D$32-Assumptions!$D$33))/(1+Assumptions!$D$32)^5)-Assumptions!$C$11+Assumptions!$C$14)/Assumptions!$C$7 -> 101.30831
A19: 0.055 | B19: =(('Historical Financials'!$G$5*(($A$19-Assumptions!$C$5*(Assumptions!$D$28+Assumptions!$C$6))*(1-Assumptions!$D$31)+Assumptions!$C$5*(Assumptions!$C$6-Assumptions!$D$29+Assumptions!$D$30))*(((1+B$16)/(1+Assumptions!$D$32))+((1+B$16)/(1+Assumptions!$D$32))^2+((1+B$16)/(1+Assumptions!$D$32))^3+((1+B$16)/(1+Assumptions!$D$32))^4+((1+B$16)/(1+Assumptions!$D$32))^5))+(('Historical Financials'!$G$5*(1+B$16)^5*(($A$19-Assumptions!$C$5*(Assumptions!$D$28+Assumptions!$C$6))*(1-Assumptions!$D$31)+Assumptions!$C$5*(Assumptions!$C$6-Assumptions!$D$29+Assumptions!$D$30))*(1+Assumptions!$D$33)/(Assumptions!$D$32-Assumptions!$D$33))/(1+Assumptions!$D$32)^5)-Assumptions!$C$11+Assumptions!$C$14)/Assumptions!$C$7 -> 70.63378 | C19: =(('Historical Financials'!$G$5*(($A$19-Assumptions!$C$5*(Assumptions!$D$28+Assumptions!$C$6))*(1-Assumptions!$D$31)+Assumptions!$C$5*(Assumptions!$C$6-Assumptions!$D$29+Assumptions!$D$30))*(((1+C$16)/(1+Assumptions!$D$32))+((1+C$16)/(1+Assumptions!$D$32))^2+((1+C$16)/(1+Assumptions!$D$32))^3+((1+C$16)/(1+Assumptions!$D$32))^4+((1+C$16)/(1+Assumptions!$D$32))^5))+(('Historical Financials'!$G$5*(1+C$16)^5*(($A$19-Assumptions!$C$5*(Assumptions!$D$28+Assumptions!$C$6))*(1-Assumptions!$D$31)+Assumptions!$C$5*(Assumptions!$C$6-Assumptions!$D$29+Assumptions!$D$30))*(1+Assumptions!$D$33)/(Assumptions!$D$32-Assumptions!$D$33))/(1+Assumptions!$D$32)^5)-Assumptions!$C$11+Assumptions!$C$14)/Assumptions!$C$7 -> 79.717668 | D19: =(('Historical Financials'!$G$5*(($A$19-Assumptions!$C$5*(Assumptions!$D$28+Assumptions!$C$6))*(1-Assumptions!$D$31)+Assumptions!$C$5*(Assumptions!$C$6-Assumptions!$D$29+Assumptions!$D$30))*(((1+D$16)/(1+Assumptions!$D$32))+((1+D$16)/(1+Assumptions!$D$32))^2+((1+D$16)/(1+Assumptions!$D$32))^3+((1+D$16)/(1+Assumptions!$D$32))^4+((1+D$16)/(1+Assumptions!$D$32))^5))+(('Historical Financials'!$G$5*(1+D$16)^5*(($A$19-Assumptions!$C$5*(Assumptions!$D$28+Assumptions!$C$6))*(1-Assumptions!$D$31)+Assumptions!$C$5*(Assumptions!$C$6-Assumptions!$D$29+Assumptions!$D$30))*(1+Assumptions!$D$33)/(Assumptions!$D$32-Assumptions!$D$33))/(1+Assumptions!$D$32)^5)-Assumptions!$C$11+Assumptions!$C$14)/Assumptions!$C$7 -> 89.782397 | E19: =(('Historical Financials'!$G$5*(($A$19-Assumptions!$C$5*(Assumptions!$D$28+Assumptions!$C$6))*(1-Assumptions!$D$31)+Assumptions!$C$5*(Assumptions!$C$6-Assumptions!$D$29+Assumptions!$D$30))*(((1+E$16)/(1+Assumptions!$D$32))+((1+E$16)/(1+Assumptions!$D$32))^2+((1+E$16)/(1+Assumptions!$D$32))^3+((1+E$16)/(1+Assumptions!$D$32))^4+((1+E$16)/(1+Assumptions!$D$32))^5))+(('Historical Financials'!$G$5*(1+E$16)^5*(($A$19-Assumptions!$C$5*(Assumptions!$D$28+Assumptions!$C$6))*(1-Assumptions!$D$31)+Assumptions!$C$5*(Assumptions!$C$6-Assumptions!$D$29+Assumptions!$D$30))*(1+Assumptions!$D$33)/(Assumptions!$D$32-Assumptions!$D$33))/(1+Assumptions!$D$32)^5)-Assumptions!$C$11+Assumptions!$C$14)/Assumptions!$C$7 -> 100.90737 | F19: =(('Historical Financials'!$G$5*(($A$19-Assumptions!$C$5*(Assumptions!$D$28+Assumptions!$C$6))*(1-Assumptions!$D$31)+Assumptions!$C$5*(Assumptions!$C$6-Assumptions!$D$29+Assumptions!$D$30))*(((1+F$16)/(1+Assumptions!$D$32))+((1+F$16)/(1+Assumptions!$D$32))^2+((1+F$16)/(1+Assumptions!$D$32))^3+((1+F$16)/(1+Assumptions!$D$32))^4+((1+F$16)/(1+Assumptions!$D$32))^5))+(('Historical Financials'!$G$5*(1+F$16)^5*(($A$19-Assumptions!$C$5*(Assumptions!$D$28+Assumptions!$C$6))*(1-Assumptions!$D$31)+Assumptions!$C$5*(Assumptions!$C$6-Assumptions!$D$29+Assumptions!$D$30))*(1+Assumptions!$D$33)/(Assumptions!$D$32-Assumptions!$D$33))/(1+Assumptions!$D$32)^5)-Assumptions!$C$11+Assumptions!$C$14)/Assumptions!$C$7 -> 113.17622
A20: 0.06 | B20: =(('Historical Financials'!$G$5*(($A$20-Assumptions!$C$5*(Assumptions!$D$28+Assumptions!$C$6))*(1-Assumptions!$D$31)+Assumptions!$C$5*(Assumptions!$C$6-Assumptions!$D$29+Assumptions!$D$30))*(((1+B$16)/(1+Assumptions!$D$32))+((1+B$16)/(1+Assumptions!$D$32))^2+((1+B$16)/(1+Assumptions!$D$32))^3+((1+B$16)/(1+Assumptions!$D$32))^4+((1+B$16)/(1+Assumptions!$D$32))^5))+(('Historical Financials'!$G$5*(1+B$16)^5*(($A$20-Assumptions!$C$5*(Assumptions!$D$28+Assumptions!$C$6))*(1-Assumptions!$D$31)+Assumptions!$C$5*(Assumptions!$C$6-Assumptions!$D$29+Assumptions!$D$30))*(1+Assumptions!$D$33)/(Assumptions!$D$32-Assumptions!$D$33))/(1+Assumptions!$D$32)^5)-Assumptions!$C$11+Assumptions!$C$14)/Assumptions!$C$7 -> 77.971191 | C20: =(('Historical Financials'!$G$5*(($A$20-Assumptions!$C$5*(Assumptions!$D$28+Assumptions!$C$6))*(1-Assumptions!$D$31)+Assumptions!$C$5*(Assumptions!$C$6-Assumptions!$D$29+Assumptions!$D$30))*(((1+C$16)/(1+Assumptions!$D$32))+((1+C$16)/(1+Assumptions!$D$32))^2+((1+C$16)/(1+Assumptions!$D$32))^3+((1+C$16)/(1+Assumptions!$D$32))^4+((1+C$16)/(1+Assumptions!$D$32))^5))+(('Historical Financials'!$G$5*(1+C$16)^5*(($A$20-Assumptions!$C$5*(Assumptions!$D$28+Assumptions!$C$6))*(1-Assumptions!$D$31)+Assumptions!$C$5*(Assumptions!$C$6-Assumptions!$D$29+Assumptions!$D$30))*(1+Assumptions!$D$33)/(Assumptions!$D$32-Assumptions!$D$33))/(1+Assumptions!$D$32)^5)-Assumptions!$C$11+Assumptions!$C$14)/Assumptions!$C$7 -> 88.022454 | D20: =(('Historical Financials'!$G$5*(($A$20-Assumptions!$C$5*(Assumptions!$D$28+Assumptions!$C$6))*(1-Assumptions!$D$31)+Assumptions!$C$5*(Assumptions!$C$6-Assumptions!$D$29+Assumptions!$D$30))*(((1+D$16)/(1+Assumptions!$D$32))+((1+D$16)/(1+Assumptions!$D$32))^2+((1+D$16)/(1+Assumptions!$D$32))^3+((1+D$16)/(1+Assumptions!$D$32))^4+((1+D$16)/(1+Assumptions!$D$32))^5))+(('Historical Financials'!$G$5*(1+D$16)^5*(($A$20-Assumptions!$C$5*(Assumptions!$D$28+Assumptions!$C$6))*(1-Assumptions!$D$31)+Assumptions!$C$5*(Assumptions!$C$6-Assumptions!$D$29+Assumptions!$D$30))*(1+Assumptions!$D$33)/(Assumptions!$D$32-Assumptions!$D$33))/(1+Assumptions!$D$32)^5)-Assumptions!$C$11+Assumptions!$C$14)/Assumptions!$C$7 -> 99.15901 | E20: =(('Historical Financials'!$G$5*(($A$20-Assumptions!$C$5*(Assumptions!$D$28+Assumptions!$C$6))*(1-Assumptions!$D$31)+Assumptions!$C$5*(Assumptions!$C$6-Assumptions!$D$29+Assumptions!$D$30))*(((1+E$16)/(1+Assumptions!$D$32))+((1+E$16)/(1+Assumptions!$D$32))^2+((1+E$16)/(1+Assumptions!$D$32))^3+((1+E$16)/(1+Assumptions!$D$32))^4+((1+E$16)/(1+Assumptions!$D$32))^5))+(('Historical Financials'!$G$5*(1+E$16)^5*(($A$20-Assumptions!$C$5*(Assumptions!$D$28+Assumptions!$C$6))*(1-Assumptions!$D$31)+Assumptions!$C$5*(Assumptions!$C$6-Assumptions!$D$29+Assumptions!$D$30))*(1+Assumptions!$D$33)/(Assumptions!$D$32-Assumptions!$D$33))/(1+Assumptions!$D$32)^5)-Assumptions!$C$11+Assumptions!$C$14)/Assumptions!$C$7 -> 111.46872 | F20: =(('Historical Financials'!$G$5*(($A$20-Assumptions!$C$5*(Assumptions!$D$28+Assumptions!$C$6))*(1-Assumptions!$D$31)+Assumptions!$C$5*(Assumptions!$C$6-Assumptions!$D$29+Assumptions!$D$30))*(((1+F$16)/(1+Assumptions!$D$32))+((1+F$16)/(1+Assumptions!$D$32))^2+((1+F$16)/(1+Assumptions!$D$32))^3+((1+F$16)/(1+Assumptions!$D$32))^4+((1+F$16)/(1+Assumptions!$D$32))^5))+(('Historical Financials'!$G$5*(1+F$16)^5*(($A$20-Assumptions!$C$5*(Assumptions!$D$28+Assumptions!$C$6))*(1-Assumptions!$D$31)+Assumptions!$C$5*(Assumptions!$C$6-Assumptions!$D$29+Assumptions!$D$30))*(1+Assumptions!$D$33)/(Assumptions!$D$32-Assumptions!$D$33))/(1+Assumptions!$D$32)^5)-Assumptions!$C$11+Assumptions!$C$14)/Assumptions!$C$7 -> 125.04412
A21: 0.065 | B21: =(('Historical Financials'!$G$5*(($A$21-Assumptions!$C$5*(Assumptions!$D$28+Assumptions!$C$6))*(1-Assumptions!$D$31)+Assumptions!$C$5*(Assumptions!$C$6-Assumptions!$D$29+Assumptions!$D$30))*(((1+B$16)/(1+Assumptions!$D$32))+((1+B$16)/(1+Assumptions!$D$32))^2+((1+B$16)/(1+Assumptions!$D$32))^3+((1+B$16)/(1+Assumptions!$D$32))^4+((1+B$16)/(1+Assumptions!$D$32))^5))+(('Historical Financials'!$G$5*(1+B$16)^5*(($A$21-Assumptions!$C$5*(Assumptions!$D$28+Assumptions!$C$6))*(1-Assumptions!$D$31)+Assumptions!$C$5*(Assumptions!$C$6-Assumptions!$D$29+Assumptions!$D$30))*(1+Assumptions!$D$33)/(Assumptions!$D$32-Assumptions!$D$33))/(1+Assumptions!$D$32)^5)-Assumptions!$C$11+Assumptions!$C$14)/Assumptions!$C$7 -> 85.308603 | C21: =(('Historical Financials'!$G$5*(($A$21-Assumptions!$C$5*(Assumptions!$D$28+Assumptions!$C$6))*(1-Assumptions!$D$31)+Assumptions!$C$5*(Assumptions!$C$6-Assumptions!$D$29+Assumptions!$D$30))*(((1+C$16)/(1+Assumptions!$D$32))+((1+C$16)/(1+Assumptions!$D$32))^2+((1+C$16)/(1+Assumptions!$D$32))^3+((1+C$16)/(1+Assumptions!$D$32))^4+((1+C$16)/(1+Assumptions!$D$32))^5))+(('Historical Financials'!$G$5*(1+C$16)^5*(($A$21-Assumptions!$C$5*(Assumptions!$D$28+Assumptions!$C$6))*(1-Assumptions!$D$31)+Assumptions!$C$5*(Assumptions!$C$6-Assumptions!$D$29+Assumptions!$D$30))*(1+Assumptions!$D$33)/(Assumptions!$D$32-Assumptions!$D$33))/(1+Assumptions!$D$32)^5)-Assumptions!$C$11+Assumptions!$C$14)/Assumptions!$C$7 -> 96.32724 | D21: =(('Historical Financials'!$G$5*(($A$21-Assumptions!$C$5*(Assumptions!$D$28+Assumptions!$C$6))*(1-Assumptions!$D$31)+Assumptions!$C$5*(Assumptions!$C$6-Assumptions!$D$29+Assumptions!$D$30))*(((1+D$16)/(1+Assumptions!$D$32))+((1+D$16)/(1+Assumptions!$D$32))^2+((1+D$16)/(1+Assumptions!$D$32))^3+((1+D$16)/(1+Assumptions!$D$32))^4+((1+D$16)/(1+Assumptions!$D$32))^5))+(('Historical Financials'!$G$5*(1+D$16)^5*(($A$21-Assumptions!$C$5*(Assumptions!$D$28+Assumptions!$C$6))*(1-Assumptions!$D$31)+Assumptions!$C$5*(Assumptions!$C$6-Assumptions!$D$29+Assumptions!$D$30))*(1+Assumptions!$D$33)/(Assumptions!$D$32-Assumptions!$D$33))/(1+Assumptions!$D$32)^5)-Assumptions!$C$11+Assumptions!$C$14)/Assumptions!$C$7 -> 108.53562 | E21: =(('Historical Financials'!$G$5*(($A$21-Assumptions!$C$5*(Assumptions!$D$28+Assumptions!$C$6))*(1-Assumptions!$D$31)+Assumptions!$C$5*(Assumptions!$C$6-Assumptions!$D$29+Assumptions!$D$30))*(((1+E$16)/(1+Assumptions!$D$32))+((1+E$16)/(1+Assumptions!$D$32))^2+((1+E$16)/(1+Assumptions!$D$32))^3+((1+E$16)/(1+Assumptions!$D$32))^4+((1+E$16)/(1+Assumptions!$D$32))^5))+(('Historical Financials'!$G$5*(1+E$16)^5*(($A$21-Assumptions!$C$5*(Assumptions!$D$28+Assumptions!$C$6))*(1-Assumptions!$D$31)+Assumptions!$C$5*(Assumptions!$C$6-Assumptions!$D$29+Assumptions!$D$30))*(1+Assumptions!$D$33)/(Assumptions!$D$32-Assumptions!$D$33))/(1+Assumptions!$D$32)^5)-Assumptions!$C$11+Assumptions!$C$14)/Assumptions!$C$7 -> 122.03007 | F21: =(('Historical Financials'!$G$5*(($A$21-Assumptions!$C$5*(Assumptions!$D$28+Assumptions!$C$6))*(1-Assumptions!$D$31)+Assumptions!$C$5*(Assumptions!$C$6-Assumptions!$D$29+Assumptions!$D$30))*(((1+F$16)/(1+Assumptions!$D$32))+((1+F$16)/(1+Assumptions!$D$32))^2+((1+F$16)/(1+Assumptions!$D$32))^3+((1+F$16)/(1+Assumptions!$D$32))^4+((1+F$16)/(1+Assumptions!$D$32))^5))+(('Historical Financials'!$G$5*(1+F$16)^5*(($A$21-Assumptions!$C$5*(Assumptions!$D$28+Assumptions!$C$6))*(1-Assumptions!$D$31)+Assumptions!$C$5*(Assumptions!$C$6-Assumptions!$D$29+Assumptions!$D$30))*(1+Assumptions!$D$33)/(Assumptions!$D$32-Assumptions!$D$33))/(1+Assumptions!$D$32)^5)-Assumptions!$C$11+Assumptions!$C$14)/Assumptions!$C$7 -> 136.91202
A24: Table 3 — Implied share price: exit EV/EBITDA (rows) × FCF margin %revenue (columns)
A25: FCF_t = FCF-margin × base-forecast revenue; terminal value = exit multiple × 2030E Adj. EBITDA. WACC at base.
A26: exit x \ FCF margin → | B26: 0.1 | C26: 0.13 | D26: 0.16 | E26: 0.19 | F26: 0.22
A27: 9 | B27: =((B$26*(Forecast!D$7/(1+Assumptions!$D$32)^1+Forecast!E$7/(1+Assumptions!$D$32)^2+Forecast!F$7/(1+Assumptions!$D$32)^3+Forecast!G$7/(1+Assumptions!$D$32)^4+Forecast!H$7/(1+Assumptions!$D$32)^5))+(($A$27*Forecast!$H$8)/(1+Assumptions!$D$32)^5)-Assumptions!$C$11+Assumptions!$C$14)/Assumptions!$C$7 -> 82.985754 | C27: =((C$26*(Forecast!D$7/(1+Assumptions!$D$32)^1+Forecast!E$7/(1+Assumptions!$D$32)^2+Forecast!F$7/(1+Assumptions!$D$32)^3+Forecast!G$7/(1+Assumptions!$D$32)^4+Forecast!H$7/(1+Assumptions!$D$32)^5))+(($A$27*Forecast!$H$8)/(1+Assumptions!$D$32)^5)-Assumptions!$C$11+Assumptions!$C$14)/Assumptions!$C$7 -> 87.483647 | D27: =((D$26*(Forecast!D$7/(1+Assumptions!$D$32)^1+Forecast!E$7/(1+Assumptions!$D$32)^2+Forecast!F$7/(1+Assumptions!$D$32)^3+Forecast!G$7/(1+Assumptions!$D$32)^4+Forecast!H$7/(1+Assumptions!$D$32)^5))+(($A$27*Forecast!$H$8)/(1+Assumptions!$D$32)^5)-Assumptions!$C$11+Assumptions!$C$14)/Assumptions!$C$7 -> 91.98154 | E27: =((E$26*(Forecast!D$7/(1+Assumptions!$D$32)^1+Forecast!E$7/(1+Assumptions!$D$32)^2+Forecast!F$7/(1+Assumptions!$D$32)^3+Forecast!G$7/(1+Assumptions!$D$32)^4+Forecast!H$7/(1+Assumptions!$D$32)^5))+(($A$27*Forecast!$H$8)/(1+Assumptions!$D$32)^5)-Assumptions!$C$11+Assumptions!$C$14)/Assumptions!$C$7 -> 96.479433 | F27: =((F$26*(Forecast!D$7/(1+Assumptions!$D$32)^1+Forecast!E$7/(1+Assumptions!$D$32)^2+Forecast!F$7/(1+Assumptions!$D$32)^3+Forecast!G$7/(1+Assumptions!$D$32)^4+Forecast!H$7/(1+Assumptions!$D$32)^5))+(($A$27*Forecast!$H$8)/(1+Assumptions!$D$32)^5)-Assumptions!$C$11+Assumptions!$C$14)/Assumptions!$C$7 -> 100.97733
A28: 11 | B28: =((B$26*(Forecast!D$7/(1+Assumptions!$D$32)^1+Forecast!E$7/(1+Assumptions!$D$32)^2+Forecast!F$7/(1+Assumptions!$D$32)^3+Forecast!G$7/(1+Assumptions!$D$32)^4+Forecast!H$7/(1+Assumptions!$D$32)^5))+(($A$28*Forecast!$H$8)/(1+Assumptions!$D$32)^5)-Assumptions!$C$11+Assumptions!$C$14)/Assumptions!$C$7 -> 97.710009 | C28: =((C$26*(Forecast!D$7/(1+Assumptions!$D$32)^1+Forecast!E$7/(1+Assumptions!$D$32)^2+Forecast!F$7/(1+Assumptions!$D$32)^3+Forecast!G$7/(1+Assumptions!$D$32)^4+Forecast!H$7/(1+Assumptions!$D$32)^5))+(($A$28*Forecast!$H$8)/(1+Assumptions!$D$32)^5)-Assumptions!$C$11+Assumptions!$C$14)/Assumptions!$C$7 -> 102.2079 | D28: =((D$26*(Forecast!D$7/(1+Assumptions!$D$32)^1+Forecast!E$7/(1+Assumptions!$D$32)^2+Forecast!F$7/(1+Assumptions!$D$32)^3+Forecast!G$7/(1+Assumptions!$D$32)^4+Forecast!H$7/(1+Assumptions!$D$32)^5))+(($A$28*Forecast!$H$8)/(1+Assumptions!$D$32)^5)-Assumptions!$C$11+Assumptions!$C$14)/Assumptions!$C$7 -> 106.7058 | E28: =((E$26*(Forecast!D$7/(1+Assumptions!$D$32)^1+Forecast!E$7/(1+Assumptions!$D$32)^2+Forecast!F$7/(1+Assumptions!$D$32)^3+Forecast!G$7/(1+Assumptions!$D$32)^4+Forecast!H$7/(1+Assumptions!$D$32)^5))+(($A$28*Forecast!$H$8)/(1+Assumptions!$D$32)^5)-Assumptions!$C$11+Assumptions!$C$14)/Assumptions!$C$7 -> 111.20369 | F28: =((F$26*(Forecast!D$7/(1+Assumptions!$D$32)^1+Forecast!E$7/(1+Assumptions!$D$32)^2+Forecast!F$7/(1+Assumptions!$D$32)^3+Forecast!G$7/(1+Assumptions!$D$32)^4+Forecast!H$7/(1+Assumptions!$D$32)^5))+(($A$28*Forecast!$H$8)/(1+Assumptions!$D$32)^5)-Assumptions!$C$11+Assumptions!$C$14)/Assumptions!$C$7 -> 115.70158
A29: 13 | B29: =((B$26*(Forecast!D$7/(1+Assumptions!$D$32)^1+Forecast!E$7/(1+Assumptions!$D$32)^2+Forecast!F$7/(1+Assumptions!$D$32)^3+Forecast!G$7/(1+Assumptions!$D$32)^4+Forecast!H$7/(1+Assumptions!$D$32)^5))+(($A$29*Forecast!$H$8)/(1+Assumptions!$D$32)^5)-Assumptions!$C$11+Assumptions!$C$14)/Assumptions!$C$7 -> 112.43426 | C29: =((C$26*(Forecast!D$7/(1+Assumptions!$D$32)^1+Forecast!E$7/(1+Assumptions!$D$32)^2+Forecast!F$7/(1+Assumptions!$D$32)^3+Forecast!G$7/(1+Assumptions!$D$32)^4+Forecast!H$7/(1+Assumptions!$D$32)^5))+(($A$29*Forecast!$H$8)/(1+Assumptions!$D$32)^5)-Assumptions!$C$11+Assumptions!$C$14)/Assumptions!$C$7 -> 116.93216 | D29: =((D$26*(Forecast!D$7/(1+Assumptions!$D$32)^1+Forecast!E$7/(1+Assumptions!$D$32)^2+Forecast!F$7/(1+Assumptions!$D$32)^3+Forecast!G$7/(1+Assumptions!$D$32)^4+Forecast!H$7/(1+Assumptions!$D$32)^5))+(($A$29*Forecast!$H$8)/(1+Assumptions!$D$32)^5)-Assumptions!$C$11+Assumptions!$C$14)/Assumptions!$C$7 -> 121.43005 | E29: =((E$26*(Forecast!D$7/(1+Assumptions!$D$32)^1+Forecast!E$7/(1+Assumptions!$D$32)^2+Forecast!F$7/(1+Assumptions!$D$32)^3+Forecast!G$7/(1+Assumptions!$D$32)^4+Forecast!H$7/(1+Assumptions!$D$32)^5))+(($A$29*Forecast!$H$8)/(1+Assumptions!$D$32)^5)-Assumptions!$C$11+Assumptions!$C$14)/Assumptions!$C$7 -> 125.92794 | F29: =((F$26*(Forecast!D$7/(1+Assumptions!$D$32)^1+Forecast!E$7/(1+Assumptions!$D$32)^2+Forecast!F$7/(1+Assumptions!$D$32)^3+Forecast!G$7/(1+Assumptions!$D$32)^4+Forecast!H$7/(1+Assumptions!$D$32)^5))+(($A$29*Forecast!$H$8)/(1+Assumptions!$D$32)^5)-Assumptions!$C$11+Assumptions!$C$14)/Assumptions!$C$7 -> 130.42584
A30: 15 | B30: =((B$26*(Forecast!D$7/(1+Assumptions!$D$32)^1+Forecast!E$7/(1+Assumptions!$D$32)^2+Forecast!F$7/(1+Assumptions!$D$32)^3+Forecast!G$7/(1+Assumptions!$D$32)^4+Forecast!H$7/(1+Assumptions!$D$32)^5))+(($A$30*Forecast!$H$8)/(1+Assumptions!$D$32)^5)-Assumptions!$C$11+Assumptions!$C$14)/Assumptions!$C$7 -> 127.15852 | C30: =((C$26*(Forecast!D$7/(1+Assumptions!$D$32)^1+Forecast!E$7/(1+Assumptions!$D$32)^2+Forecast!F$7/(1+Assumptions!$D$32)^3+Forecast!G$7/(1+Assumptions!$D$32)^4+Forecast!H$7/(1+Assumptions!$D$32)^5))+(($A$30*Forecast!$H$8)/(1+Assumptions!$D$32)^5)-Assumptions!$C$11+Assumptions!$C$14)/Assumptions!$C$7 -> 131.65641 | D30: =((D$26*(Forecast!D$7/(1+Assumptions!$D$32)^1+Forecast!E$7/(1+Assumptions!$D$32)^2+Forecast!F$7/(1+Assumptions!$D$32)^3+Forecast!G$7/(1+Assumptions!$D$32)^4+Forecast!H$7/(1+Assumptions!$D$32)^5))+(($A$30*Forecast!$H$8)/(1+Assumptions!$D$32)^5)-Assumptions!$C$11+Assumptions!$C$14)/Assumptions!$C$7 -> 136.15431 | E30: =((E$26*(Forecast!D$7/(1+Assumptions!$D$32)^1+Forecast!E$7/(1+Assumptions!$D$32)^2+Forecast!F$7/(1+Assumptions!$D$32)^3+Forecast!G$7/(1+Assumptions!$D$32)^4+Forecast!H$7/(1+Assumptions!$D$32)^5))+(($A$30*Forecast!$H$8)/(1+Assumptions!$D$32)^5)-Assumptions!$C$11+Assumptions!$C$14)/Assumptions!$C$7 -> 140.6522 | F30: =((F$26*(Forecast!D$7/(1+Assumptions!$D$32)^1+Forecast!E$7/(1+Assumptions!$D$32)^2+Forecast!F$7/(1+Assumptions!$D$32)^3+Forecast!G$7/(1+Assumptions!$D$32)^4+Forecast!H$7/(1+Assumptions!$D$32)^5))+(($A$30*Forecast!$H$8)/(1+Assumptions!$D$32)^5)-Assumptions!$C$11+Assumptions!$C$14)/Assumptions!$C$7 -> 145.15009
